Workbook

Sheet thermal_summary_attribute_table
A1: Irrig | B1: date | C1: ID | D1: genotype | E1: phenology | F1: conductance | G1: leaftemp | H1: yield | I1: temp.mean | J1: temp.median | K1: temp.sd | L1: temp.se | M1: temp.cv | N1: temp.min | O1: temp.max | P1: temp.range
A2: Rainfed | B2: 45513 | C2: 1 | D2: P42A84E | E2: R4 | F2: 0.89290067 | G2: 29.24 | H2: 1516.9584 | I2: 39.870056 | J2: 39.57201 | K2: 1.2133072 | L2: 0.0018774243 | M2: 3.0431539 | N2: 37.728027 | O2: 44.525623 | P2: 6.797596
A3: Rainfed | B3: 45513 | C3: 2 | D3: P48A14E | E3: R4 | F3: 0.67524367 | G3: 30.19 | H3: 1449.6718 | I3: 39.346141 | J3: 39.26832 | K3: 0.69014458 | L3: 0.0010679029 | M3: 1.7540337 | N3: 36.869278 | O3: 41.710899 | P3: 4.8416214
A4: Rainfed | B4: 45513 | C4: 3 | D4: P52A14SE | E4: R3 | F4: 0.63957967 | G4: 31.446667 | H4: 1321.116 | I4: 38.646962 | J4: 38.500526 | K4: 1.047553 | L4: 0.0016209428 | M4: 2.7105701 | N4: 35.162773 | O4: 43.505196 | P4: 8.3424225
A5: Rainfed | B5: 45513 | C5: 4 | D5: R19C-1012 | E5: R3 | F5: 0.55055533 | G5: 32.213333 | H5: 1450.2188 | I5: 39.653648 | J5: 39.429873 | K5: 1.3901129 | L5: 0.0021510066 | M5: 3.5056368 | N5: 36.448673 | O5: 43.627636 | P5: 7.1789627
A6: Rainfed | B6: 45513 | C6: 5 | D6: R18-14502 | E6: R3 | H6: 271.33479 | I6: 38.996262 | J6: 38.919727 | K6: 1.1196279 | L6: 0.0017324687 | M6: 2.871116 | N6: 34.788944 | O6: 42.557343 | P6: 7.7683983
A7: Rainfed | B7: 45513 | C7: 6 | D7: R18C-13665 | E7: R2 | H7: 2586.9803 | I7: 38.929242 | J7: 38.906904 | K7: 1.0734034 | L7: 0.0016609426 | M7: 2.7573189 | N7: 33.199474 | O7: 42.157715 | P7: 8.9582405
A8: Rainfed | B8: 45513 | C8: 7 | D8: R19-46252 | E8: R2 | H8: 1771.8818 | I8: 38.92701 | J8: 38.936934 | K8: 0.92182667 | L8: 0.0014263987 | M8: 2.3680901 | N8: 35.063202 | O8: 41.064686 | P8: 6.0014839
A9: Rainfed | B9: 45513 | C9: 8 | D9: R19-45980 | E9: R3 | H9: 1237.965 | I9: 37.891695 | J9: 37.767578 | K9: 1.181654 | L9: 0.0018284455 | M9: 3.118504 | N9: 33.694374 | O9: 42.486465 | P9: 8.7920914
A10: Rainfed | B10: 45513 | C10: 9 | D10: PI398245 | E10: R2 | F10: 0.75610333 | G10: 31.526667 | H10: 952.95405 | I10: 40.770579 | J10: 41.004248 | K10: 0.99354906 | L10: 0.0015373792 | M10: 2.4369266 | N10: 38.299786 | O10: 42.867931 | P10: 4.5681458
A11: Rainfed | B11: 45513 | C11: 10 | D11: PI377574 | E11: R2 | F11: 0.040697333 | G11: 34.063333 | H11: 856.12691 | I11: 39.929108 | J11: 40.036211 | K11: 1.1485818 | L11: 0.0017772708 | M11: 2.8765525 | N11: 37.035118 | O11: 42.95332 | P11: 5.9182014
A12: Rainfed | B12: 45513 | C12: 11 | D12: PI424397 | E12: R4 | F12: 0.035785 | G12: 33.016667 | H12: 910.83151 | I12: 39.765984 | J12: 39.471935 | K12: 1.1245076 | L12: 0.0017400194 | M12: 2.8278129 | N12: 38.181622 | O12: 45.968437 | P12: 7.7868156
A13: Rainfed | B13: 45513 | C13: 12 | D13: PI567488B | E13: R3 | F13: 0.052778667 | G13: 31.97 | H13: 1498.9059 | I13: 38.320972 | J13: 38.287861 | K13: 0.79594308 | L13: 0.0012316114 | M13: 2.077043 | N13: 36.308125 | O13: 42.087635 | P13: 5.7795105
A14: Rainfed | B14: 45513 | C14: 13 | D14: PI377574 | E14: R3 | F14: 0.048692333 | G14: 32.556667 | H14: 586.43326 | I14: 39.013923 | J14: 39.095665 | K14: 0.92015846 | L14: 0.0014238174 | M14: 2.3585387 | N14: 36.136894 | O14: 41.702637 | P14: 5.5657425
A15: Rainfed | B15: 45513 | C15: 14 | D15: R19-45980 | E15: R2 | H15: 1647.1554 | I15: 37.678905 | J15: 37.564178 | K15: 0.87752747 | L15: 0.0013578519 | M15: 2.3289622 | N15: 35.255547 | O15: 42.784531 | P15: 7.5289841
A16: Rainfed | B16: 45513 | C16: 15 | D16: PI398245 | E16: R2 | F16: 0.048151 | G16: 32.77 | H16: 1360.5033 | I16: 38.340821 | J16: 38.065136 | K16: 1.0034679 | L16: 0.0015527271 | M16: 2.617231 | N16: 36.349648 | O16: 42.437618 | P16: 6.0879707
A17: Rainfed | B17: 45513 | C17: 16 | D17: P48A14E | E17: R5 | F17: 0.025598 | G17: 32.916667 | H17: 1636.2144 | I17: 38.07292 | J17: 38.12912 | K17: 0.89783959 | L17: 0.0013892821 | M17: 2.3582105 | N17: 34.319336 | O17: 41.831406 | P17: 7.5120697
A18: Rainfed | B18: 45513 | C18: 17 | D18: R19-46252 | E18: R2 | H18: 1438.1838 | I18: 38.097439 | J18: 38.166378 | K18: 1.0318185 | L18: 0.0015965958 | M18: 2.7083671 | N18: 33.5359 | O18: 40.989002 | P18: 7.4531021
A19: Rainfed | B19: 45513 | C19: 18 | D19: R19C-1012 | E19: R3 | F19: 0.040080333 | G19: 34.116667 | H19: 1684.9015 | I19: 37.513201 | J19: 37.593338 | K19: 0.91990293 | L19: 0.001423422 | M19: 2.4522112 | N19: 32.783222 | O19: 39.960274 | P19: 7.1770515
A20: Rainfed | B20: 45513 | C20: 19 | D20: R18-14502 | E20: R4 | H20: 1712.2538 | I20: 38.007535 | J20: 37.807451 | K20: 0.99032426 | L20: 0.0015323892 | M20: 2.6055998 | N20: 35.157089 | O20: 41.316601 | P20: 6.1595116
A21: Rainfed | B21: 45513 | C21: 20 | D21: PI424397 | E21: R5 | F21: 0.048795333 | G21: 33.546667 | H21: 894.96718 | I21: 39.615195 | J21: 39.432247 | K21: 1.5569226 | L21: 0.0024091216 | M21: 3.9301148 | N21: 34.819454 | O21: 43.629707 | P21: 8.8102531
A22: Rainfed | B22: 45513 | C22: 21 | D22: P42A84E | E22: R4 | F22: 0.031484333 | G22: 31.793333 | H22: 1430.5252 | I22: 38.759491 | J22: 38.743633 | K22: 1.2762721 | L22: 0.0019748538 | M22: 3.292799 | N22: 34.907227 | O22: 42.638184 | P22: 7.730957
A23: Rainfed | B23: 45513 | C23: 22 | D23: PI567488B | E23: R3 | F23: 0.046344667 | G23: 32.11 | H23: 1812.3632 | I23: 37.584205 | J23: 37.554123 | K23: 1.1437789 | L23: 0.001769839 | M23: 3.0432436 | N23: 34.578964 | O23: 41.348732 | P23: 6.7697678
A24: Rainfed | B24: 45513 | C24: 23 | D24: R18C-13665 | E24: R2 | H24: 1802.5164 | I24: 38.194434 | J24: 38.096329 | K24: 1.0851799 | L24: 0.0016791651 | M24: 2.841199 | N24: 35.630604 | O24: 42.211601 | P24: 6.5809975
A25: Rainfed | B25: 45513 | C25: 24 | D25: P52A14SE | E25: R3 | F25: 0.052981333 | G25: 31.726667 | H25: 1613.7856 | I25: 39.687305 | J25: 39.807423 | K25: 1.0618121 | L25: 0.0016430067 | M25: 2.6754452 | N25: 36.884884 | O25: 42.680389 | P25: 5.7955055
A26: Rainfed | B26: 45513 | C26: 25 | D26: P48A14E | E26: R5 | F26: 0.061534667 | G26: 33.163333 | H26: 1796.4989 | I26: 38.55528 | J26: 38.543341 | K26: 0.96087005 | L26: 0.0014868129 | M26: 2.492188 | N26: 35.864628 | O26: 41.979374 | P26: 6.1147461
A27: Rainfed | B27: 45513 | C27: 26 | D27: P42A84E | E27: R5 | F27: 0.063075 | G27: 33.663333 | H27: 1636.7615 | I27: 39.371932 | J27: 39.215233 | K27: 1.0892291 | L27: 0.0016854307 | M27: 2.7665116 | N27: 36.507248 | O27: 42.527695 | P27: 6.0204468
A28: Rainfed | B28: 45513 | C28: 27 | D28: R19-45980 | E28: R2 | H28: 1442.5602 | I28: 37.281907 | J28: 37.213028 | K28: 0.78630952 | L28: 0.0012167048 | M28: 2.1090915 | N28: 34.423321 | O28: 39.803829 | P28: 5.3805084
A29: Rainfed | B29: 45513 | C29: 28 | D29: PI398245 | E29: R3 | F29: 0.062447 | G29: 33.876667 | H29: 1736.8709 | I29: 37.722667 | J29: 37.722519 | K29: 0.77984447 | L29: 0.001206701 | M29: 2.06731 | N29: 34.237892 | O29: 39.923885 | P29: 5.6859932
A30: Rainfed | B30: 45513 | C30: 29 | D30: PI567488B | E30: R4 | F30: 0.050953 | G30: 34.646667 | H30: 1681.0722 | I30: 35.770132 | J30: 35.845615 | K30: 0.93771183 | L30: 0.0014509788 | M30: 2.6214939 | N30: 31.394922 | O30: 38.150822 | P30: 6.7558994
A31: Rainfed | B31: 45513 | C31: 30 | D31: PI424397 | E31: R5 | F31: 0.061006333 | G31: 35.05 | H31: 1155.9081 | I31: 38.669901 | J31: 38.713154 | K31: 1.0119188 | L31: 0.0015658038 | M31: 2.6168125 | N31: 33.653984 | O31: 41.625118 | P31: 7.9711342
A32: Rainfed | B32: 45513 | C32: 31 | D32: PI377574 | E32: R3 | F32: 0.090889667 | G32: 33.766667 | H32: 691.46608 | I32: 37.122406 | J32: 37.144989 | K32: 1.6044885 | L32: 0.0024827231 | M32: 4.3221566 | N32: 31.911777 | O32: 40.548283 | P32: 8.6365051
A33: Rainfed | B33: 45513 | C33: 32 | D33: P52A14SE | E33: R2 | F33: 0.085518 | G33: 33.513333 | H33: 1548.14 | I33: 37.24663 | J33: 37.027491 | K33: 1.3392708 | L33: 0.0020723355 | M33: 3.5956832 | N33: 33.550255 | O33: 42.120567 | P33: 8.5703125
A34: Rainfed | B34: 45513 | C34: 33 | D34: R19C-1012 | E34: R3 | F34: 0.07144 | G34: 34.06 | H34: 2449.1247 | I34: 36.623936 | J34: 36.413176 | K34: 1.2896202 | L34: 0.0019955081 | M34: 3.5212496 | N34: 33.930801 | O34: 41.557716 | P34: 7.626915
A35: Rainfed | B35: 45513 | C35: 34 | D35: R18C-13665 | E35: R3 | H35: 1916.849 | I35: 38.073995 | J35: 37.786289 | K35: 1.4412497 | L35: 0.0022301337 | M35: 3.7853913 | N35: 34.933029 | O35: 42.855194 | P35: 7.9221649
A36: Rainfed | B36: 45513 | C36: 35 | D36: R18-14502 | E36: R4 | H36: 2071.116 | I36: 37.356876 | J36: 37.321486 | K36: 1.0788198 | L36: 0.0016693238 | M36: 2.8878748 | N36: 34.730213 | O36: 42.785099 | P36: 8.0548859
A37: Rainfed | B37: 45513 | C37: 36 | D37: R19-46252 | E37: R2 | H37: 1861.0503 | I37: 38.107754 | J37: 37.913349 | K37: 1.26984 | L37: 0.0019649011 | M37: 3.3322354 | N37: 35.706932 | O37: 45.07246 | P37: 9.3655281
A38: Irrigated | B38: 45513 | C38: 37 | D38: P42A84E | E38: R4 | F38: 0.173181 | G38: 32.083333 | H38: 3729.7593 | I38: 31.547478 | J38: 31.60082 | K38: 0.76247059 | L38: 0.0011798173 | M38: 2.4168987 | N38: 29.147032 | O38: 33.570156 | P38: 4.4231243
A39: Irrigated | B39: 45513 | C39: 38 | D39: P48A14E | E39: R3 | F39: 0.17416867 | G39: 31.623333 | H39: 5551.9694 | I39: 30.949634 | J39: 30.934629 | K39: 0.6453 | L39: 0.00099851213 | M39: 2.0850004 | N39: 29.387266 | O39: 33.122871 | P39: 3.7356052
A40: Irrigated | B40: 45513 | C40: 39 | D40: P52A14SE | E40: R3 | F40: 0.582617 | G40: 30.253333 | H40: 3612.1444 | I40: 31.821078 | J40: 31.879238 | K40: 0.5293228 | L40: 0.00081905351 | M40: 1.6634345 | N40: 30.166817 | O40: 33.251991 | P40: 3.0851746
...

Sheet Sheet2
A3: Row Labels | B3: Average of temp.mean
A4: 45513 | B4: 34.930231
A5: Irrigated | B5: 31.278238
A6: Rainfed | B6: 38.582225
A7: 45534 | B7: 31.776981
A8: Irrigated | B8: 31.046974
A9: Rainfed | B9: 32.506988
A10: (blank)
A11: (blank)
A12: Grand Total | B12: 33.578838

Sheet mm
A1: Irrig | B1: date | C1: ID | D1: genotype | E1: phenology | F1: conductance | G1: leaftemp | H1: yield | I1: temp.mean | J1: temp.median | K1: temp.sd | L1: temp.se | M1: temp.cv | N1: temp.min | O1: temp.max | P1: temp.range | Q1: diftemp | R1: yield(bu/ac) | T1: irrigated | U1: =AVERAGE(I44:I85) -> 31.179125 | V1: rainfed | W1: =AVERAGE(I2:I43) -> 35.978552 | Y1: =W1-U1 -> 4.7994269
A2: Rainfed | B2: 45513 | C2: 4 | D2: R19C-1012 | E2: R3 | F2: 0.55055533 | G2: 32.213333 | H2: 1450.2188 | I2: 39.653648 | J2: 39.429873 | K2: 1.3901129 | L2: 0.0021510066 | M2: 3.5056368 | N2: 36.448673 | O2: 43.627636 | P2: 7.1789627 | Q2: =+G2-I2 -> -7.4403145 | R2: =H2/67.19 -> 21.583849
A3: Rainfed | B3: 45513 | C3: 18 | D3: R19C-1012 | E3: R3 | F3: 0.040080333 | G3: 34.116667 | H3: 1684.9015 | I3: 37.513201 | J3: 37.593338 | K3: 0.91990293 | L3: 0.001423422 | M3: 2.4522112 | N3: 32.783222 | O3: 39.960274 | P3: 7.1770515 | Q3: =+G3-I3 -> -3.3965347 | R3: =H3/67.19 -> 25.076671
A4: Rainfed | B4: 45513 | C4: 33 | D4: R19C-1012 | E4: R3 | F4: 0.07144 | G4: 34.06 | H4: 2449.1247 | I4: 36.623936 | J4: 36.413176 | K4: 1.2896202 | L4: 0.0019955081 | M4: 3.5212496 | N4: 33.930801 | O4: 41.557716 | P4: 7.626915 | Q4: =+G4-I4 -> -2.5639355 | R4: =H4/67.19 -> 36.450733
A5: Rainfed | B5: 45513 | C5: 12 | D5: PI567488B | E5: R3 | F5: 0.052778667 | G5: 31.97 | H5: 1498.9059 | I5: 38.320972 | J5: 38.287861 | K5: 0.79594308 | L5: 0.0012316114 | M5: 2.077043 | N5: 36.308125 | O5: 42.087635 | P5: 5.7795105 | Q5: =+G5-I5 -> -6.3509725 | R5: =H5/67.19 -> 22.308467
A6: Rainfed | B6: 45534 | C6: 12 | D6: PI567488B | E6: R6 | F6: 0.73217367 | G6: 27.366667 | H6: 1498.9059 | I6: 33.135862 | J6: 33.098007 | K6: 0.46794084 | L6: 0.00077964481 | M6: 1.4121885 | N6: 31.996504 | O6: 34.75172 | P6: 2.7552166 | Q6: =+G6-I6 -> -5.7691954 | R6: =H6/67.19 -> 22.308467
A7: Rainfed | B7: 45513 | C7: 22 | D7: PI567488B | E7: R3 | F7: 0.046344667 | G7: 32.11 | H7: 1812.3632 | I7: 37.584205 | J7: 37.554123 | K7: 1.1437789 | L7: 0.001769839 | M7: 3.0432436 | N7: 34.578964 | O7: 41.348732 | P7: 6.7697678 | Q7: =+G7-I7 -> -5.4742053 | R7: =H7/67.19 -> 26.973705
A8: Rainfed | B8: 45534 | C8: 22 | D8: PI567488B | E8: R5.8 | F8: 0.22531867 | G8: 30.66 | H8: 1812.3632 | I8: 32.595482 | J8: 32.557392 | K8: 0.42157272 | L8: 0.00070239004 | M8: 1.2933471 | N8: 31.376211 | O8: 33.920292 | P8: 2.5440807 | Q8: =+G8-I8 -> -1.9354824 | R8: =H8/67.19 -> 26.973705
A9: Rainfed | B9: 45513 | C9: 29 | D9: PI567488B | E9: R4 | F9: 0.050953 | G9: 34.646667 | H9: 1681.0722 | I9: 35.770132 | J9: 35.845615 | K9: 0.93771183 | L9: 0.0014509788 | M9: 2.6214939 | N9: 31.394922 | O9: 38.150822 | P9: 6.7558994 | Q9: =+G9-I9 -> -1.1234649 | R9: =H9/67.19 -> 25.019679
A10: Rainfed | B10: 45534 | C10: 29 | D10: PI567488B | E10: R5.8 | F10: 0.32994833 | G10: 31.556667 | H10: 1681.0722 | I10: 32.298268 | J10: 32.275509 | K10: 0.39015674 | L10: 0.0006500473 | M10: 1.2079804 | N10: 31.15666 | O10: 33.479687 | P10: 2.3230267 | Q10: =+G10-I10 -> -0.74160182 | R10: =H10/67.19 -> 25.019679
A11: Rainfed | B11: 45513 | C11: 11 | D11: PI424397 | E11: R4 | F11: 0.035785 | G11: 33.016667 | H11: 910.83151 | I11: 39.765984 | J11: 39.471935 | K11: 1.1245076 | L11: 0.0017400194 | M11: 2.8278129 | N11: 38.181622 | O11: 45.968437 | P11: 7.7868156 | Q11: =+G11-I11 -> -6.7493175 | R11: =H11/67.19 -> 13.556058
A12: Rainfed | B12: 45534 | C12: 11 | D12: PI424397 | E12: R5 | F12: 0.65567333 | G12: 27.52 | H12: 910.83151 | I12: 32.383283 | J12: 32.324764 | K12: 0.37862779 | L12: 0.0006308387 | M12: 1.1692075 | N12: 31.520391 | O12: 35.114044 | P12: 3.5936527 | Q12: =+G12-I12 -> -4.8632834 | R12: =H12/67.19 -> 13.556058
A13: Rainfed | B13: 45513 | C13: 20 | D13: PI424397 | E13: R5 | F13: 0.048795333 | G13: 33.546667 | H13: 894.96718 | I13: 39.615195 | J13: 39.432247 | K13: 1.5569226 | L13: 0.0024091216 | M13: 3.9301148 | N13: 34.819454 | O13: 43.629707 | P13: 8.8102531 | Q13: =+G13-I13 -> -6.0685282 | R13: =H13/67.19 -> 13.319946
... A85: Irrigated | B85: 45534 | C85: 62 | D85: P42A84E | E85: R5.8 | F85: 1.534967 | G85: 34.223333 | H85: 4184.9015 | I85: 31.125224 | J85: 31.065508 | K85: 0.37139634 | L85: 0.00061879025 | M85: 1.1932327 | N85: 30.289082 | O85: 32.122482 | P85: 1.8334007 | Q85: =+G85-I85 -> 3.0981095 | R85: =H85/67.19 -> 62.284589

Sheet Sheet1
I1: difference
A2: irrigated | B2: R19C-1012 | C2: =AVERAGE(mm!I44:I46) -> 30.885103 | E2: R19C-1012 | F2: =AVERAGE(mm!I2:I4) -> 37.930262 | G2: rainfed | I2: =F2-C2 -> 7.0451583
B3: PI567488B | C3: =AVERAGE(mm!I47:I53) -> 30.763985 | E3: PI567488B | F3: =AVERAGE(mm!I5:I10) -> 34.95082 | I3: =F3-C3 -> 4.1868352
B4: PI424397 | C4: =AVERAGE(mm!I54:I59) -> 31.937928 | E4: PI424397 | F4: =AVERAGE(mm!I11:I16) -> 35.786656 | I4: =F4-C4 -> 3.8487278
B5: PI398245 | C5: =AVERAGE(mm!I60:I67) -> 31.51515 | E5: PI398245 | F5: =AVERAGE(mm!I17:I22) -> 35.638571 | I5: =F5-C5 -> 4.1234212
B6: PI377574 | C6: =AVERAGE(mm!I68:I73) -> 30.978934 | E6: PI377574 | F6: =AVERAGE(mm!I23:I28) -> 35.354477 | I6: =F6-C6 -> 4.3755428
B7: P52A14SE | C7: =AVERAGE(mm!I74:I75) -> 31.65142 | E7: P52A14SE | F7: =AVERAGE(mm!I29:I31) -> 38.526966 | I7: =F7-C7 -> 6.8755453
B8: P48A14E | C8: =AVERAGE(mm!I76:I79) -> 30.939408 | E8: P48A14E | F8: =AVERAGE(mm!I32:I37) -> 35.849606 | I8: =F8-C8 -> 4.9101979
B9: P42A84E | C9: =AVERAGE(mm!I80:I85) -> 30.8062 | E9: P42A84E | F9: =AVERAGE(mm!I38:I43) -> 36.04112 | I9: =F9-C9 -> 5.2349198
